<?xml version="1.0"?>
<robot  name="basic_robot" >
 <link  name="link1" >
  <visual >
   <origin  rpy="0 0 0"  xyz="0.25 0 0" />
   <geometry >
    <box  size="0.5 0.12 0.12" />
   </geometry>
   <material  name="link1_material" >
    <color  rgba="0.9174756541192329 0.8762602017382229 0.5446987936566259 0.2" />
   </material>
  </visual>
  <collision >
   <origin  rpy="0 0 0"  xyz="0.25 0 0" />
   <geometry >
    <box  size="0.5 0.12 0.12" />
   </geometry>
  </collision>
  <inertial >
   <origin  rpy="0 0 0"  xyz="0.25 0 0" />
   <mass  value="5" />
   <inertia  izz="0.4226666666666667"  ixx="0.106"  ixy="0"  iyz="0"  ixz="0"  iyy="0.4226666666666667" />
  </inertial>
 </link>
 <link  name="link2" >
  <visual >
   <origin  rpy="0 0 0"  xyz="0.25 0 0" />
   <geometry >
    <box  size="0.5 0.11 0.11" />
   </geometry>
   <material  name="link2_material" >
    <color  rgba="0.39284838413773693 0.8490635282216377 0.2909041756510121 0.2" />
   </material>
  </visual>
  <collision >
   <origin  rpy="0 0 0"  xyz="0.25 0 0" />
   <geometry >
    <box  size="0.5 0.11 0.11" />
   </geometry>
  </collision>
  <inertial >
   <origin  rpy="0 0 0"  xyz="0.25 0 0" />
   <mass  value="5" />
   <inertia  izz="0.42170833333333335"  ixx="0.09670833333333334"  ixy="0"  iyz="0"  ixz="0"  iyy="0.42170833333333335" />
  </inertial>
 </link>
 <link  name="base_link" >
  <visual >
   <origin  rpy="0 0 0"  xyz="0.3 0 0" />
   <geometry >
    <box  size="0.6 0.2 0.2" />
   </geometry>
   <material  name="base_link_material" >
    <color  rgba="0.1547887920023292 0.9360495464899368 0.93206446751931 0.2" />
   </material>
  </visual>
  <collision >
   <origin  rpy="0 0 0"  xyz="0.3 0 0" />
   <geometry >
    <box  size="0.6 0.2 0.2" />
   </geometry>
  </collision>
  <inertial >
   <origin  rpy="0 0 0"  xyz="0.3 0 0" />
   <mass  value="5" />
   <inertia  izz="0.5166666666666667"  ixx="0.18333333333333335"  ixy="0"  iyz="0"  ixz="0"  iyy="0.5166666666666667" />
  </inertial>
 </link>
 <link  name="link3" >
  <visual >
   <origin  rpy="0 0 0"  xyz="0.3 0 0" />
   <geometry >
    <box  size="0.6 0.14 0.12" />
   </geometry>
   <material  name="link3_material" >
    <color  rgba="0.6779871336456591 0.4732600889646632 0.4248651166155757 0.2" />
   </material>
  </visual>
  <collision >
   <origin  rpy="0 0 0"  xyz="0.3 0 0" />
   <geometry >
    <box  size="0.6 0.14 0.12" />
   </geometry>
  </collision>
  <inertial >
   <origin  rpy="0 0 0"  xyz="0.3 0 0" />
   <mass  value="5" />
   <inertia  izz="0.5081666666666667"  ixx="0.12266666666666669"  ixy="0"  iyz="0"  ixz="0"  iyy="0.5059999999999999" />
  </inertial>
 </link>
 <link  name="link4" >
  <visual >
   <origin  rpy="0 0 0"  xyz="0.3 0 0" />
   <geometry >
    <box  size="0.6 0.11 0.16" />
   </geometry>
   <material  name="link4_material" >
    <color  rgba="0.521099661256421 0.3005862301729352 0.417710189840244 0.2" />
   </material>
  </visual>
  <collision >
   <origin  rpy="0 0 0"  xyz="0.3 0 0" />
   <geometry >
    <box  size="0.6 0.11 0.16" />
   </geometry>
  </collision>
  <inertial >
   <origin  rpy="0 0 0"  xyz="0.3 0 0" />
   <mass  value="5" />
   <inertia  izz="0.5050416666666666"  ixx="0.10233333333333333"  ixy="0"  iyz="0"  ixz="0"  iyy="0.5106666666666667" />
  </inertial>
 </link>
 <joint  type="revolute"  name="joint1" >
  <origin  rpy="0 0 0"  xyz="0.5 0 0" />
  <parent  link="link1" />
  <child  link="link2" />
  <axis  xyz="0 0 1" />
  <limit  effort="5"  lower="-3.141592653589793"  velocity="50"  upper="3.141592653589793" />
 </joint>
 <joint  type="revolute"  name="joint2" >
  <origin  rpy="0 0 0"  xyz="0.6 0 0" />
  <parent  link="base_link" />
  <child  link="link1" />
  <axis  xyz="0 0 1" />
  <limit  effort="5"  lower="-3.141592653589793"  velocity="50"  upper="3.141592653589793" />
 </joint>
 <joint  type="revolute"  name="joint3" >
  <origin  rpy="0 0 3.14159"  xyz="0.0 0 0" />
  <parent  link="base_link" />
  <child  link="link3" />
  <axis  xyz="0 0 1" />
  <limit  effort="5"  lower="-3.141592653589793"  velocity="50"  upper="3.141592653589793" />
 </joint>
 <joint  type="revolute"  name="joint4" >
  <origin  rpy="0 0 0"  xyz="0.6 0 0" />
  <parent  link="link3" />
  <child  link="link4" />
  <axis  xyz="0 0 1" />
  <limit  effort="5"  lower="-3.141592653589793"  velocity="50"  upper="3.141592653589793" />
 </joint>
 <joint  type="fixed"  name="joint5" >
  <origin  rpy="0 0 0"  xyz="0.6 0 0" />
  <parent  link="link4" />
  <child  link="link5_psedo" />
  <axis  xyz="0 0 0" />
 </joint>
 <joint  type="revolute"  name="joint6" >
  <origin  rpy="0 0 0"  xyz="0.5 0 0" />
  <parent  link="link2" />
  <child  link="link6_psedo" />
  <axis  xyz="0 0 1" />
  <limit  effort="5"  velocity="50" />
 </joint>
 <link  name="link6_psedo" >
  <visual >
   <origin  rpy="0 0 0"  xyz="0 0 0" />
   <geometry >
    <sphere  radius="0.1" />
   </geometry>
   <material  name="link6_psedo_material" >
    <color  rgba="0.22975774033044838 0.7104728288350008 0.8010084447803063 0.2" />
   </material>
  </visual>
  <inertial >
   <origin  rpy="0 0 0"  xyz="0 0 0" />
   <mass  value="1e-09" />
   <inertia  izz="0.0"  ixx="0.0"  ixy="0"  iyz="0"  ixz="0"  iyy="0.0" />
  </inertial>
 </link>
 <link  name="link5_psedo" >
  <visual >
   <origin  rpy="0 0 0"  xyz="0 0 0" />
   <geometry >
    <sphere  radius="0.1" />
   </geometry>
   <material  name="link5_psedo_material" >
    <color  rgba="0.45907991034241613 0.06044172251685431 0.3008860408413019 0.2" />
   </material>
  </visual>
  <inertial >
   <origin  rpy="0 0 0"  xyz="0 0 0" />
   <mass  value="1e-09" />
   <inertia  izz="0.0"  ixx="0.0"  ixy="0"  iyz="0"  ixz="0"  iyy="0.0" />
  </inertial>
 </link>
</robot>
