<?xml version="1.0"?>
<robot  name="Robot" >
 <link  name="L3" >
  <visual >
   <origin  rpy="0.0 4.440892098500626e-16 0.0"  xyz="-5.041410108656904e-17 0.0 0.11240305297740992" />
   <geometry >
    <box  size="0.04 0.04 0.18480610595481983" />
   </geometry>
   <material  name="L3_Material" >
    <color  rgba="0.9489204915836907 0.40456783254169204 0.13490998075837624 1.0" />
   </material>
  </visual>
  <collision  name="L3_0_Collision" >
   <origin  rpy="0.0 4.440892098500626e-16 0.0"  xyz="-5.041410108656904e-17 0.0 0.11240305297740992" />
   <geometry >
    <box  size="0.04 0.04 0.18480610595481983" />
   </geometry>
  </collision>
  <visual >
   <origin  rpy="0.0 0.6315989704892955 0.0"  xyz="0.058285535929490054 0.0 0.3044783285873756" />
   <geometry >
    <box  size="0.04 0.04 0.15743218337241185" />
   </geometry>
   <material  name="L3_Material" >
    <color  rgba="0.9489204915836907 0.40456783254169204 0.13490998075837624 1.0" />
   </material>
  </visual>
  <collision  name="L3_1_Collision" >
   <origin  rpy="0.0 0.6315989704892955 0.0"  xyz="0.058285535929490054 0.0 0.3044783285873756" />
   <geometry >
    <box  size="0.04 0.04 0.15743218337241185" />
   </geometry>
  </collision>
  <visual >
   <origin  rpy="0.0 0.29462031839762415 0.0"  xyz="0.0582855359294901 0.0 0.19207527560996568" />
   <geometry >
    <box  size="0.04 0.04 0.3614479552780518" />
   </geometry>
   <material  name="L3_Material" >
    <color  rgba="0.9489204915836907 0.40456783254169204 0.13490998075837624 1.0" />
   </material>
  </visual>
  <collision  name="L3_2_Collision" >
   <origin  rpy="0.0 0.29462031839762415 0.0"  xyz="0.0582855359294901 0.0 0.19207527560996568" />
   <geometry >
    <box  size="0.04 0.04 0.3614479552780518" />
   </geometry>
  </collision>
  <inertial >
   <origin  rpy="0.0 0.0 0.0"  xyz="0.03886 0.0 0.20299" />
   <mass  value="0.7075589957531151" />
   <inertia  ixz="-0.0012452211811197105"  ixy="1.9058241313221758e-20"  iyy="0.00492692421305846"  izz="0.0006285016584430776"  ixx="0.004487104953482881"  iyz="0.0" />
  </inertial>
 </link>
 <link  name="G" >
  <visual >
   <origin  rpy="0.0 0.0 0.0"  xyz="0.0 0.0 0.0" />
   <geometry >
    <box  size="0.08 0.08 0.08" />
   </geometry>
   <material  name="G_Material" >
    <color  rgba="0.7720277480230913 0.6396255314372624 0.0379761331688907 1.0" />
   </material>
  </visual>
  <collision  name="G_Collision" >
   <origin  rpy="0.0 0.0 0.0"  xyz="0.0 0.0 0.0" />
   <geometry >
    <box  size="0.08 0.08 0.08" />
   </geometry>
  </collision>
  <inertial >
   <origin  rpy="0.0 0.0 0.0"  xyz="0.0 0.0 0.0" />
   <mass  value="1.3824000000000003" />
   <inertia  ixz="0.0"  ixy="0.0"  iyy="0.0014745600000000004"  izz="0.0014745600000000004"  ixx="0.0014745600000000004"  iyz="0.0" />
  </inertial>
 </link>
 <link  name="L4" >
  <visual >
   <origin  rpy="0.0 0.0 0.0"  xyz="0.0 0.0 0.12406" />
   <geometry >
    <box  size="0.04 0.04 0.208113159193445" />
   </geometry>
   <material  name="L4_Material" >
    <color  rgba="0.6321513744780578 0.08481510651894797 0.660215021700418 1.0" />
   </material>
  </visual>
  <collision  name="L4_Collision" >
   <origin  rpy="0.0 0.0 0.0"  xyz="0.0 0.0 0.12406" />
   <geometry >
    <box  size="0.04 0.04 0.208113159193445" />
   </geometry>
  </collision>
  <inertial >
   <origin  rpy="0.0 0.0 0.0"  xyz="0.0 0.0 0.12406" />
   <mass  value="0.8990488477156825" />
   <inertia  ixz="0.0"  ixy="0.0"  iyy="0.003364771753625774"  izz="0.00023974635939084867"  ixx="0.003364771753625774"  iyz="0.0" />
  </inertial>
 </link>
 <link  name="L5" >
  <visual >
   <origin  rpy="0.0 0.0 0.0"  xyz="0.0 0.0 0.05905165835078802" />
   <geometry >
    <box  size="0.04 0.04 0.0781033167015758" />
   </geometry>
   <material  name="L5_Material" >
    <color  rgba="0.191132139875961 0.5383635488816468 0.7808682506141833 1.0" />
   </material>
  </visual>
  <collision  name="L5_0_Collision" >
   <origin  rpy="0.0 0.0 0.0"  xyz="0.0 0.0 0.05905165835078802" />
   <geometry >
    <box  size="0.04 0.04 0.0781033167015758" />
   </geometry>
  </collision>
  <visual >
   <origin  rpy="-3.141592653589793 -0.023665528281153314 3.141592653589793"  xyz="-0.001366455961445301 0.0 0.06037374321211447" />
   <geometry >
    <box  size="0.04 0.04 0.0754914863904643" />
   </geometry>
   <material  name="L5_Material" >
    <color  rgba="0.191132139875961 0.5383635488816468 0.7808682506141833 1.0" />
   </material>
  </visual>
  <collision  name="L5_1_Collision" >
   <origin  rpy="-3.141592653589793 -0.023665528281153314 3.141592653589793"  xyz="-0.001366455961445301 0.0 0.06037374321211447" />
   <geometry >
    <box  size="0.04 0.04 0.0754914863904643" />
   </geometry>
  </collision>
  <visual >
   <origin  rpy="0.0 -0.8019004503912998 0.0"  xyz="-0.001366455961445301 0.0 0.0013220848613265668" />
   <geometry >
    <box  size="0.04 0.04 -0.03619731133269209" />
   </geometry>
   <material  name="L5_Material" >
    <color  rgba="0.191132139875961 0.5383635488816468 0.7808682506141833 1.0" />
   </material>
  </visual>
  <collision  name="L5_2_Collision" >
   <origin  rpy="0.0 -0.8019004503912998 0.0"  xyz="-0.001366455961445301 0.0 0.0013220848613265668" />
   <geometry >
    <box  size="0.04 0.04 -0.03619731133269209" />
   </geometry>
  </collision>
  <inertial >
   <origin  rpy="0.0 0.0 0.0"  xyz="-0.00091 0.0 0.04025" />
   <mass  value="0.008714680983359854" />
   <inertia  ixz="-7.463480966324103e-08"  ixy="-4.652890945610781e-24"  iyy="6.608908401209273e-06"  izz="1.1655734879568412e-06"  ixx="7.767249842148391e-06"  iyz="0.0" />
  </inertial>
 </link>
 <link  name="EE" >
  <visual >
   <origin  rpy="0.0 0.0 0.0"  xyz="0.0 0.0 0.0" />
   <geometry >
    <sphere  radius="0.028571428571428574" />
   </geometry>
   <material  name="EE_Material" >
    <color  rgba="0.6200764478738867 0.7600747533648031 0.22089966309379028 1.0" />
   </material>
  </visual>
  <collision  name="EE_Collision" >
   <origin  rpy="0.0 0.0 0.0"  xyz="0.0 0.0 0.0" />
   <geometry >
    <sphere  radius="0.028571428571428574" />
   </geometry>
  </collision>
  <inertial >
   <origin  rpy="0.0 0.0 0.0"  xyz="0.0 0.0 0.0" />
   <mass  value="0.2637838729544783" />
   <inertia  ixz="0.0"  ixy="0.0"  iyy="8.61335095361562e-05"  izz="8.61335095361562e-05"  ixx="8.61335095361562e-05"  iyz="0.0" />
  </inertial>
 </link>
 <link  name="L6" >
  <visual >
   <origin  rpy="0.0 0.0 0.0"  xyz="-0.0 0.0 0.20446" />
   <geometry >
    <box  size="0.04 0.04 0.3689280977973105" />
   </geometry>
   <material  name="L6_Material" >
    <color  rgba="0.4376078047882892 0.7513060956113852 0.11816608908444337 1.0" />
   </material>
  </visual>
  <collision  name="L6_Collision" >
   <origin  rpy="0.0 0.0 0.0"  xyz="-0.0 0.0 0.20446" />
   <geometry >
    <box  size="0.04 0.04 0.3689280977973105" />
   </geometry>
  </collision>
  <inertial >
   <origin  rpy="0.0 0.0 0.0"  xyz="-0.0 0.0 0.20446" />
   <mass  value="1.5937693824843815" />
   <inertia  ixz="0.0"  ixy="0.0"  iyy="0.0182895583866306"  izz="0.00042500516866250177"  ixx="0.0182895583866306"  iyz="0.0" />
  </inertial>
 </link>
 <joint  name="G0main"  type="revolute" >
  <parent  link="G" />
  <child  link="L3" />
  <origin  rpy="3.141592653589793 -0.1940721171876849 3.141592653589793"  xyz="0.0 0.0 0.0" />
  <axis  xyz="0 1 0" />
  <limit  velocity="17.907078125461823"  upper="3.141592653589793"  effort="5.3999999999999995"  lower="-3.141592653589793" />
  <dynamics  friction="0"  damping="0.05" />
 </joint>
 <joint  name="G0main_G_WeldActuator"  type="fixed" >
  <parent  link="G" />
  <child  link="G0main_GActuator" />
  <origin  rpy="-1.5707963267948966 -0.1940721171876849 -3.141592653589793"  xyz="0.0 0.05975 0.0" />
 </joint>
 <link  name="G0main_GActuator" >
  <visual >
   <geometry >
    <cylinder  length="0.0395"  radius="0.034" />
   </geometry>
   <material  name="G0main_GActuator_Material" >
    <color  rgba="0.7720277480230913 0.6396255314372624 0.0379761331688907 0.9" />
   </material>
  </visual>
  <inertial >
   <inertia  ixz="0.0"  ixy="0.0"  iyy="0.004339333333333334"  izz="0.006256"  ixx="0.004339333333333334"  iyz="0.0" />
   <mass  value="0.1" />
  </inertial>
 </link>
 <link  name="G0main_GUnit" >
  <visual >
   <geometry >
    <cylinder  length="0.08"  radius="0.04" />
   </geometry>
   <material  name="G0main_GUnit_Material" >
    <color  rgba="0.7720277480230913 0.6396255314372624 0.0379761331688907 0.9" />
   </material>
  </visual>
  <inertial >
   <inertia  ixz="0.0"  ixy="0.0"  iyy="0.0016666666666666666"  izz="0.002"  ixx="0.0016666666666666666"  iyz="0.0" />
   <mass  value="0.1" />
  </inertial>
 </link>
 <joint  name="G0main_G_WeldUnit"  type="fixed" >
  <parent  link="G" />
  <child  link="G0main_GUnit" />
  <origin  rpy="-1.5707963267948966 -0.1940721171876849 -3.141592653589793"  xyz="0.0 0.0 0.0" />
 </joint>
 <joint  name="J0m"  type="revolute" >
  <parent  link="L3" />
  <child  link="L4" />
  <origin  rpy="0.0 -0.1853619848621504 0.0"  xyz="0.1165710718589802 0.0 0.38415055121993136" />
  <axis  xyz="0 1 0" />
  <limit  velocity="6.283185307179586"  upper="3.141592653589793"  effort="600.0"  lower="-3.141592653589793" />
  <dynamics  friction="0"  damping="0.05" />
 </joint>
 <link  name="J0m_L3Unit" >
  <visual >
   <geometry >
    <cylinder  length="0.04"  radius="0.02" />
   </geometry>
   <material  name="J0m_L3Unit_Material" >
    <color  rgba="0.9489204915836907 0.40456783254169204 0.13490998075837624 0.9" />
   </material>
  </visual>
  <inertial >
   <inertia  ixz="0.0"  ixy="0.0"  iyy="0.0008333333333333333"  izz="0.001"  ixx="0.0008333333333333333"  iyz="0.0" />
   <mass  value="0.1" />
  </inertial>
 </link>
 <joint  name="J0m_L3_WeldUnit"  type="fixed" >
  <parent  link="L3" />
  <child  link="J0m_L3Unit" />
  <origin  rpy="1.5707963267948966 -0.1853619848621504 0.0"  xyz="0.1165710718589802 0.0 0.38415055121993136" />
 </joint>
 <link  name="J1m_L4Pseudo" >
  <visual >
   <geometry >
    <sphere  radius="0.028571428571428574" />
   </geometry>
   <material  name="J1m_L4Pseudo_Material" >
    <color  rgba="0.6321513744780578 0.08481510651894797 0.660215021700418 0.5" />
   </material>
  </visual>
 </link>
 <joint  name="J1m_L4_revolute"  type="revolute" >
  <parent  link="L4" />
  <child  link="J1m_L4Pseudo" />
  <origin  rpy="0.0 0.0 0.0"  xyz="6.38378239159465e-16 0.0 0.24811315919344507" />
  <axis  xyz="0 1 0" />
  <limit  velocity="6.283185307179586"  upper="3.141592653589793"  effort="600.0"  lower="-3.141592653589793" />
  <dynamics  friction="0"  damping="0.05" />
 </joint>
 <joint  name="J1m_L4_Weld"  type="fixed" >
  <parent  link="L5" />
  <child  link="J1m_L5Pseudo" />
  <origin  rpy="0.0 0.2849311239419876 0.0"  xyz="-0.002732911922890574 0.0 0.002644169722653078" />
 </joint>
 <link  name="J1m_L5Pseudo" >
  <visual >
   <geometry >
    <sphere  radius="0.028571428571428574" />
   </geometry>
   <material  name="J1m_L5Pseudo_Material" >
    <color  rgba="0.191132139875961 0.5383635488816468 0.7808682506141833 0.5" />
   </material>
  </visual>
 </link>
 <joint  name="Jee"  type="fixed" >
  <parent  link="L5" />
  <child  link="EE" />
  <origin  rpy="3.141592653589793 -0.27622099161645286 3.141592653589793"  xyz="0.0 0.0 0.11810331670157592" />
 </joint>
 <link  name="Jee_L5Unit" >
  <visual >
   <geometry >
    <cylinder  length="0.04"  radius="0.02" />
   </geometry>
   <material  name="Jee_L5Unit_Material" >
    <color  rgba="0.191132139875961 0.5383635488816468 0.7808682506141833 0.9" />
   </material>
  </visual>
  <inertial >
   <inertia  ixz="0.0"  ixy="0.0"  iyy="0.0008333333333333333"  izz="0.001"  ixx="0.0008333333333333333"  iyz="0.0" />
   <mass  value="0.1" />
  </inertial>
 </link>
 <joint  name="Jee_L5_WeldUnit"  type="fixed" >
  <parent  link="L5" />
  <child  link="Jee_L5Unit" />
  <origin  rpy="-1.570796326794897 -0.27622099161645286 3.1415926535897927"  xyz="0.0 0.0 0.11810331670157592" />
 </joint>
 <joint  name="J0_0"  type="revolute" >
  <parent  link="L3" />
  <child  link="L6" />
  <origin  rpy="0.0 0.18315120050913536 0.0"  xyz="-1.0082820217313808e-16 0.0 0.22480610595481984" />
  <axis  xyz="0 1 0" />
  <limit  velocity="6.283185307179586"  upper="3.141592653589793"  effort="600.0"  lower="-3.141592653589793" />
  <dynamics  friction="0"  damping="0.05" />
 </joint>
 <link  name="J0_0_L3Unit" >
  <visual >
   <geometry >
    <cylinder  length="0.04"  radius="0.02" />
   </geometry>
   <material  name="J0_0_L3Unit_Material" >
    <color  rgba="0.9489204915836907 0.40456783254169204 0.13490998075837624 0.9" />
   </material>
  </visual>
  <inertial >
   <inertia  ixz="0.0"  ixy="0.0"  iyy="0.0008333333333333333"  izz="0.001"  ixx="0.0008333333333333333"  iyz="0.0" />
   <mass  value="0.1" />
  </inertial>
 </link>
 <joint  name="J0_0_L3_WeldUnit"  type="fixed" >
  <parent  link="L3" />
  <child  link="J0_0_L3Unit" />
  <origin  rpy="1.5707963267948966 0.18315120050913536 -1.1102230246251565e-16"  xyz="-1.0082820217313808e-16 0.0 0.22480610595481984" />
 </joint>
 <joint  name="J1_0"  type="revolute" >
  <parent  link="L6" />
  <child  link="L5" />
  <origin  rpy="0.0 -0.6534443093132728 0.0"  xyz="-9.71445146547012e-17 0.0 0.40892809779731043" />
  <axis  xyz="0 1 0" />
  <limit  velocity="6.283185307179586"  upper="3.141592653589793"  effort="600.0"  lower="-3.141592653589793" />
  <dynamics  friction="0"  damping="0.05" />
 </joint>
 <link  name="J1_0_L6Unit" >
  <visual >
   <geometry >
    <cylinder  length="0.04"  radius="0.02" />
   </geometry>
   <material  name="J1_0_L6Unit_Material" >
    <color  rgba="0.4376078047882892 0.7513060956113852 0.11816608908444337 0.9" />
   </material>
  </visual>
  <inertial >
   <inertia  ixz="0.0"  ixy="0.0"  iyy="0.0008333333333333333"  izz="0.001"  ixx="0.0008333333333333333"  iyz="0.0" />
   <mass  value="0.1" />
  </inertial>
 </link>
 <joint  name="J1_0_L6_WeldUnit"  type="fixed" >
  <parent  link="L6" />
  <child  link="J1_0_L6Unit" />
  <origin  rpy="1.5707963267948961 -0.6534443093132728 2.220446049250313e-16"  xyz="-9.71445146547012e-17 0.0 0.40892809779731043" />
 </joint>
</robot>
