<?xml version="1.0"?>
<robot  name="Robot" >
 <link  name="G" >
  <visual >
   <origin  rpy="0.0 0.0 0.0"  xyz="0.0 0.0 0.0" />
   <geometry >
    <sphere  radius="0.02" />
   </geometry>
   <material name="G_">
    <color  rgba="0.0954734058300698 0.6863410020852343 0.8024111207497548 0.7" />
   </material>
  </visual>
  <collision  name="G_collision" >
   <origin  rpy="0.0 0.0 0.0"  xyz="0.0 0.0 0.0" />
   <geometry >
    <sphere  radius="0.02" />
   </geometry>
  </collision>
  <inertial >
   <origin  rpy="0.0 0.0 0.0"  xyz="0.0 0.0 0.0" />
   <mass  value="0.09047786842338605" />
   <inertia  iyy="1.447645894774177e-05"  ixy="0.0"  iyz="0.0"  izz="1.447645894774177e-05"  ixx="1.447645894774177e-05"  ixz="0.0" />
  </inertial>
 </link>
 <link  name="L3" >
  <visual >
   <origin  rpy="0.0 0.0 0.0"  xyz="-0.0 0.0 0.08505" />
   <geometry >
    <box  size="0.02 0.02 0.17009106226542423" />
   </geometry>
   <material name="L3_" >
    <color  rgba="0.13379381071996344 0.682614603861126 0.187152451877447 0.7" />
   </material>
  </visual>
  <collision  name="L3_collision" >
   <origin  rpy="0.0 0.0 0.0"  xyz="-0.0 0.0 0.08505" />
   <geometry >
    <box  size="0.02 0.02 0.17009106226542423" />
   </geometry>
  </collision>
  <inertial >
   <origin  rpy="0.0 0.0 0.0"  xyz="-0.0 0.0 0.08505" />
   <mass  value="0.18369834724665818" />
   <inertia  iyy="0.0004490042177848521"  ixy="0.0"  iyz="0.0"  izz="1.2246556483110546e-05"  ixx="0.0004490042177848521"  ixz="0.0" />
  </inertial>
 </link>
 <link  name="L4" >
  <visual >
   <origin  rpy="0.0 3.9968028886505635e-15 0.0"  xyz="-6.522560269672795e-16 0.0 0.10074578964399047" />
   <geometry >
    <box  size="0.02 0.02 0.20149157928798095" />
   </geometry>
   <material name="L4_0_">
    <color  rgba="0.002729469653218519 0.21214175388818712 0.6494953943440573 0.7" />
   </material>
  </visual>
  <collision  name="L4_0collision" >
   <origin  rpy="0.0 3.9968028886505635e-15 0.0"  xyz="-6.522560269672795e-16 0.0 0.10074578964399047" />
   <geometry >
    <box  size="0.02 0.02 0.20149157928798095" />
   </geometry>
  </collision>
  <visual >
   <origin  rpy="-3.141592653589793 -0.7330038377215442 3.141592653589793"  xyz="-0.04995018574532388 0.0 0.14601243464203995" />
   <geometry >
    <box  size="0.02 0.02 0.14930447477068423" />
   </geometry>
   <material name="L4_1_">
    <color  rgba="0.002729469653218519 0.21214175388818712 0.6494953943440573 0.7" />
   </material>
  </visual>
  <collision  name="L4_1collision" >
   <origin  rpy="-3.141592653589793 -0.7330038377215442 3.141592653589793"  xyz="-0.04995018574532388 0.0 0.14601243464203995" />
   <geometry >
    <box  size="0.02 0.02 0.14930447477068423" />
   </geometry>
  </collision>
  <visual >
   <origin  rpy="0.0 -0.8345467114834904 0.0"  xyz="-0.04995018574532323 0.0 0.04526664499804948" />
   <geometry >
    <box  size="0.02 0.02 0.13481973454018858" />
   </geometry>
   <material  name="Grey" >
    <color  rgba="0.002729469653218519 0.21214175388818712 0.6494953943440573 0.7" />
   </material>
  </visual>
  <collision  name="L4_2collision" >
   <origin  rpy="0.0 -0.8345467114834904 0.0"  xyz="-0.04995018574532323 0.0 0.04526664499804948" />
   <geometry >
    <box  size="0.02 0.02 0.13481973454018858" />
   </geometry>
  </collision>
  <inertial >
   <origin  rpy="0.0 0.0 0.0"  xyz="-0.0333 0.0 0.09734" />
   <mass  value="0.5434852578238679" />
   <inertia  iyy="0.0012238539751903456"  ixy="-2.3822801641527197e-21"  iyz="0.0"  izz="0.0003194511001340029"  ixx="0.0009406352255779352"  ixz="-3.0804518113879015e-05" />
  </inertial>
 </link>
 <link  name="EE" >
  <visual >
   <origin  rpy="0.0 -1.2846999394537875 0.0"  xyz="-0.05532615236569652 0.0 0.01627509956849034" />
   <geometry >
    <box  size="0.02 0.02 0.11534057398082494" />
   </geometry>
   <material  name="Grey" >
    <color  rgba="0.030517297167252155 0.5492296900372909 0.5292564916721271 0.7" />
   </material>
  </visual>
  <collision  name="EE_0collision" >
   <origin  rpy="0.0 -1.2846999394537875 0.0"  xyz="-0.05532615236569652 0.0 0.01627509956849034" />
   <geometry >
    <box  size="0.02 0.02 0.11534057398082494" />
   </geometry>
  </collision>
  <visual >
   <origin  rpy="0.0 0.0 0.0"  xyz="-2.7755575615628914e-17 0.0 0.08908449652431631" />
   <geometry >
    <box  size="0.02 0.02 0.17816899304863262" />
   </geometry>
   <material  name="Grey" >
    <color  rgba="0.030517297167252155 0.5492296900372909 0.5292564916721271 0.7" />
   </material>
  </visual>
  <collision  name="EE_1collision" >
   <origin  rpy="0.0 0.0 0.0"  xyz="-2.7755575615628914e-17 0.0 0.08908449652431631" />
   <geometry >
    <box  size="0.02 0.02 0.17816899304863262" />
   </geometry>
  </collision>
  <visual >
   <origin  rpy="0.0 0.6497921842703738 0.0"  xyz="-0.05532615236569652 0.0 0.10535959609280665" />
   <geometry >
    <box  size="0.02 0.02 0.18289003713339122" />
   </geometry>
   <material  name="Grey" >
    <color  rgba="0.030517297167252155 0.5492296900372909 0.5292564916721271 0.7" />
   </material>
  </visual>
  <collision  name="EE_2collision" >
   <origin  rpy="0.0 0.6497921842703738 0.0"  xyz="-0.05532615236569652 0.0 0.10535959609280665" />
   <geometry >
    <box  size="0.02 0.02 0.18289003713339122" />
   </geometry>
  </collision>
  <inertial >
   <origin  rpy="0.0 0.0 0.0"  xyz="-0.03688 0.0 0.07024" />
   <mass  value="0.5322998622375738" />
   <inertia  iyy="0.0011606562566164776"  ixy="-2.3822801641527197e-21"  iyz="0.0"  izz="0.0003798235380043869"  ixx="0.0008163193760945958"  ixz="-0.00018499343359396807" />
  </inertial>
 </link>
 <link  name="L7" >
  <visual >
   <origin  rpy="0.0 0.0 0.0"  xyz="0.0 0.0 0.07909" />
   <geometry >
    <box  size="0.02 0.02 0.15818269265163623" />
   </geometry>
   <material  name="Grey" >
    <color  rgba="0.8131390989523208 0.032618147700333555 0.18467411937387623 0.7" />
   </material>
  </visual>
  <collision  name="L7_collision" >
   <origin  rpy="0.0 0.0 0.0"  xyz="0.0 0.0 0.07909" />
   <geometry >
    <box  size="0.02 0.02 0.15818269265163623" />
   </geometry>
  </collision>
  <inertial >
   <origin  rpy="0.0 0.0 0.0"  xyz="0.0 0.0 0.07909" />
   <mass  value="0.17083730806376712" />
   <inertia  iyy="0.00036191548095618664"  ixy="0.0"  iyz="0.0"  izz="1.1389153870917808e-05"  ixx="0.00036191548095618664"  ixz="0.0" />
  </inertial>
 </link>
 <link  name="L5" >
  <visual >
   <origin  rpy="0.0 0.9372251978037345 0.0"  xyz="0.06739366594956714 0.0 0.049507292791440886" />
   <geometry >
    <box  size="0.02 0.02 0.16724686244781156" />
   </geometry>
   <material  name="Grey" >
    <color  rgba="0.057848240900274295 0.08733543179576186 0.37535930635435677 0.7" />
   </material>
  </visual>
  <collision  name="L5_0collision" >
   <origin  rpy="0.0 0.9372251978037345 0.0"  xyz="0.06739366594956714 0.0 0.049507292791440886" />
   <geometry >
    <box  size="0.02 0.02 0.16724686244781156" />
   </geometry>
  </collision>
  <visual >
   <origin  rpy="0.0 0.0 0.0"  xyz="-2.7755575615628914e-17 0.0 0.09209051063036233" />
   <geometry >
    <box  size="0.02 0.02 0.18418102126072466" />
   </geometry>
   <material  name="Grey" >
    <color  rgba="0.057848240900274295 0.08733543179576186 0.37535930635435677 0.7" />
   </material>
  </visual>
  <collision  name="L5_1collision" >
   <origin  rpy="0.0 0.0 0.0"  xyz="-2.7755575615628914e-17 0.0 0.09209051063036233" />
   <geometry >
    <box  size="0.02 0.02 0.18418102126072466" />
   </geometry>
  </collision>
  <visual >
   <origin  rpy="0.0 -1.0072807061778266 0.0"  xyz="0.06739366594956711 0.0 0.14159780342180323" />
   <geometry >
    <box  size="0.02 0.02 0.15943947631172006" />
   </geometry>
   <material  name="Grey" >
    <color  rgba="0.057848240900274295 0.08733543179576186 0.37535930635435677 0.7" />
   </material>
  </visual>
  <collision  name="L5_2collision" >
   <origin  rpy="0.0 -1.0072807061778266 0.0"  xyz="0.06739366594956711 0.0 0.14159780342180323" />
   <geometry >
    <box  size="0.02 0.02 0.15943947631172006" />
   </geometry>
  </collision>
  <inertial >
   <origin  rpy="0.0 0.0 0.0"  xyz="0.04493 0.0 0.0944" />
   <mass  value="0.6702822479391518" />
   <inertia  iyy="0.0016257157520202065"  ixy="4.7645603283054394e-21"  iyz="0.0"  izz="0.0006988669875613168"  ixx="0.0009715342476548335"  ixz="-3.47533008795298e-05" />
  </inertial>
 </link>
 <link  name="L6" >
  <visual >
   <origin  rpy="0.0 0.0 0.0"  xyz="-0.0 0.0 0.11013" />
   <geometry >
    <box  size="0.02 0.02 0.22026245267476668" />
   </geometry>
   <material  name="Grey" >
    <color  rgba="0.36746002221645724 0.16067203637069882 0.9699104142487472 0.7" />
   </material>
  </visual>
  <collision  name="L6_collision" >
   <origin  rpy="0.0 0.0 0.0"  xyz="-0.0 0.0 0.11013" />
   <geometry >
    <box  size="0.02 0.02 0.22026245267476668" />
   </geometry>
  </collision>
  <inertial >
   <origin  rpy="0.0 0.0 0.0"  xyz="-0.0 0.0 0.11013" />
   <mass  value="0.23788344888874804" />
   <inertia  iyy="0.0009696832730327181"  ixy="0.0"  iyz="0.0"  izz="1.5858896592583204e-05"  ixx="0.0009696832730327181"  ixz="0.0" />
  </inertial>
 </link>
 <joint  name="Gabs"  type="revolute" >
  <parent  link="G" />
  <child  link="L3" />
  <origin  rpy="0.0 0.7547270559595018 0.0"  xyz="0.0 0.0 0.0" />
  <axis  xyz="0 1 0" />
  <limit  upper="3.141592653589793"  velocity="17.907078125461823"  lower="-3.141592653589793"  effort="5.3999999999999995" />
  <dynamics  damping="0.05"  friction="0" />
 </joint>
 <joint  name="Gabs_G_WeldActuator"  type="fixed" >
  <parent  link="G" />
  <child  link="Gabs_GActuator" />
  <origin  rpy="1.5707963267948966 0.7547270559595018 1.1102230246251565e-16"  xyz="0.0 0.0 0.0" />
 </joint>
 <link  name="Gabs_GActuator" >
  <visual >
   <geometry >
    <cylinder  radius="0.01"  length="0.0395" />
   </geometry>
   <material  name="Grey" >
    <color  rgba="0.0954734058300698 0.6863410020852343 0.8024111207497548 0.7" />
   </material>
  </visual>
 </link>
 <joint  name="J1m"  type="revolute" >
  <parent  link="L3" />
  <child  link="L4" />
  <origin  rpy="0.0 -0.767884191432251 0.0"  xyz="-4.0807089294978096e-18 0.0 0.1700910622654242" />
  <axis  xyz="0 1 0" />
  <limit  upper="3.141592653589793"  velocity="17.907078125461823"  lower="-3.141592653589793"  effort="5.3999999999999995" />
  <dynamics  damping="0.05"  friction="0" />
 </joint>
 <joint  name="J1m_L3_WeldActuator"  type="fixed" >
  <parent  link="L3" />
  <child  link="J1m_L3Actuator" />
  <origin  rpy="1.5707963267948961 -0.7678841914322511 1.1102230246251565e-16"  xyz="-4.0807089294978096e-18 0.0 0.1700910622654242" />
 </joint>
 <link  name="J1m_L3Actuator" >
  <visual >
   <geometry >
    <cylinder  radius="0.01"  length="0.0395" />
   </geometry>
   <material name = "J1m_L3Actuator__">
    <color  rgba="0.13379381071996344 0.682614603861126 0.187152451877447 0.7" />
   </material>
  </visual>
 </link>
 <joint  name="J2m"  type="revolute" >
  <parent  link="L4" />
  <child  link="EE" />
  <origin  rpy="0.0 1.1585038248976036 0.0"  xyz="-1.304512053934559e-15 0.0 0.20149157928798095" />
  <axis  xyz="0 1 0" />
  <limit  upper="3.141592653589793"  velocity="6.283185307179586"  lower="-3.141592653589793"  effort="600.0" />
  <dynamics  damping="0.05"  friction="0" />
 </joint>
 <joint  name="G2"  type="revolute" >
  <parent  link="G" />
  <child  link="L7" />
  <origin  rpy="0.0 0.2851056794268283 0.0"  xyz="-0.18464620786146133 0.0 0.0" />
  <axis  xyz="0 1 0" />
  <limit  upper="3.141592653589793"  velocity="6.283185307179586"  lower="-3.141592653589793"  effort="600.0" />
  <dynamics  damping="0.05"  friction="0" />
 </joint>
 <joint  name="J1b1"  type="revolute" >
  <parent  link="L7" />
  <child  link="L5" />
  <origin  rpy="0.0 -0.026921955112103158 0.0"  xyz="2.7755575615628914e-17 0.0 0.15818269265163623" />
  <axis  xyz="0 1 0" />
  <limit  upper="3.141592653589793"  velocity="6.283185307179586"  lower="-3.141592653589793"  effort="600.0" />
  <dynamics  damping="0.05"  friction="0" />
 </joint>
 <link  name="J2b1_L5Pseudo" >
  <visual >
   <geometry >
    <sphere  radius="0.014285714285714287" />
   </geometry>
   <material  name="Grey" >
    <color  rgba="0.057848240900274295 0.08733543179576186 0.37535930635435677 0.5" />
   </material>
  </visual>
 </link>
 <joint  name="J2b1_L5_revolute"  type="revolute" >
  <parent  link="L5" />
  <child  link="J2b1_L5Pseudo" />
  <origin  rpy="0.0 0.0 0.0"  xyz="0.13478733189913428 0.0 0.09901458558288179" />
  <axis  xyz="0 1 0" />
  <limit  upper="3.141592653589793"  velocity="6.283185307179586"  lower="-3.141592653589793"  effort="600.0" />
  <dynamics  damping="0.05"  friction="0" />
 </joint>
 <joint  name="J2b1_L5_fix"  type="fixed" >
  <parent  link="L4" />
  <child  link="J2b1_L4Pseudo" />
  <origin  rpy="0.0 0.27134085978747424 0.0"  xyz="-0.09990037149064651 0.0 0.09053328999609891" />
 </joint>
 <link  name="J2b1_L4Pseudo" >
  <visual >
   <geometry >
    <sphere  radius="0.014285714285714287" />
   </geometry>
   <material  name="Grey" >
    <color  rgba="0.002729469653218519 0.21214175388818712 0.6494953943440573 0.5" />
   </material>
  </visual>
 </link>
 <joint  name="J1b2"  type="revolute" >
  <parent  link="L5" />
  <child  link="L6" />
  <origin  rpy="0.0 0.7911298922393728 0.0"  xyz="-5.551115123125783e-17 0.0 0.18418102126072466" />
  <axis  xyz="0 1 0" />
  <limit  upper="3.141592653589793"  velocity="6.283185307179586"  lower="-3.141592653589793"  effort="600.0" />
  <dynamics  damping="0.05"  friction="0" />
 </joint>
 <link  name="J2b2_L6Pseudo" >
  <visual >
   <geometry >
    <sphere  radius="0.014285714285714287" />
   </geometry>
   <material  name="Grey" >
    <color  rgba="0.36746002221645724 0.16067203637069882 0.9699104142487472 0.5" />
   </material>
  </visual>
 </link>
 <joint  name="J2b2_L6_revolute"  type="revolute" >
  <parent  link="L6" />
  <child  link="J2b2_L6Pseudo" />
  <origin  rpy="0.0 0.0 0.0"  xyz="0.0 0.0 0.22026245267476663" />
  <axis  xyz="0 1 0" />
  <limit  upper="3.141592653589793"  velocity="6.283185307179586"  lower="-3.141592653589793"  effort="600.0" />
  <dynamics  damping="0.05"  friction="0" />
 </joint>
 <joint  name="J2b2_L6_fix"  type="fixed" >
  <parent  link="EE" />
  <child  link="J2b2_EEPseudo" />
  <origin  rpy="0.0 -0.09603307287075635 0.0"  xyz="-0.110652304731393 0.0 0.032550199136980595" />
 </joint>
 <link  name="J2b2_EEPseudo" >
  <visual >
   <geometry >
    <sphere  radius="0.014285714285714287" />
   </geometry>
   <material  name="Grey" >
    <color  rgba="0.030517297167252155 0.5492296900372909 0.5292564916721271 0.5" />
   </material>
  </visual>
 </link>
</robot>
