<?xml version="1.0"?>
<robot  name="Robot" >
 <link  name="L7" >
  <visual >
   <origin  rpy="0.0 0.0 0.0"  xyz="2.2558598182634495e-18 0.0 0.23043881490459198" />
   <geometry >
    <box  size="0.02 0.02 0.46087762980918395" />
   </geometry>
   <material  name="L7_">
    <color  rgba="0.22805773121194928 0.6120967953154014 0.1518055185515783 0.7" />
   </material>
  </visual>
  <collision  name="L7_0collision" >
   <origin  rpy="0.0 0.0 0.0"  xyz="2.2558598182634495e-18 0.0 0.23043881490459198" />
   <geometry >
    <box  size="0.02 0.02 0.46087762980918395" />
   </geometry>
  </collision>
  <visual >
   <origin  rpy="-3.141592653589793 -0.07190014748544638 3.141592653589793"  xyz="-0.011418202738261123 0.0 0.30234499271936227" />
   <geometry >
    <box  size="0.02 0.02 0.317886598499686" />
   </geometry>
   <material name="L7_">
    <color  rgba="0.22805773121194928 0.6120967953154014 0.1518055185515783 0.7" />
   </material>
  </visual>
  <collision  name="L7_1collision" >
   <origin  rpy="-3.141592653589793 -0.07190014748544638 3.141592653589793"  xyz="-0.011418202738261123 0.0 0.30234499271936227" />
   <geometry >
    <box  size="0.02 0.02 0.317886598499686" />
   </geometry>
  </collision>
  <visual >
   <origin  rpy="0.0 -0.15747823743771439 0.0"  xyz="-0.011418202738261125 0.0 0.07190617781477031" />
   <geometry >
    <box  size="0.02 0.02 0.14561419933099107" />
   </geometry>
   <material name="L7_">
    <color  rgba="0.22805773121194928 0.6120967953154014 0.1518055185515783 0.7" />
   </material>
  </visual>
  <collision  name="L7_2collision" >
   <origin  rpy="0.0 -0.15747823743771439 0.0"  xyz="-0.011418202738261125 0.0 0.07190617781477031" />
   <geometry >
    <box  size="0.02 0.02 0.14561419933099107" />
   </geometry>
  </collision>
  <inertial >
   <origin  rpy="0.0 0.0 0.0"  xyz="-0.00761 0.0 0.20156" />
   <mass  value="0.14839951685427272" />
   <inertia  iyy="0.0013795531334773483"  ixx="0.0013802003079160677"  ixy="6.119627755455107e-22"  izz="9.246126684898068e-06"  ixz="-1.6309410470624286e-05"  iyz="-7.763056961585554e-23" />
  </inertial>
 </link>
 <link  name="G" >
  <visual >
   <origin  rpy="0.0 0.0 0.0"  xyz="0.0 0.0 0.0" />
   <geometry >
    <sphere  radius="0.02" />
   </geometry>
   <material name="G_">
    <color  rgba="0.6471661013432043 0.7522130508474295 0.9849666425566113 0.7" />
   </material>
  </visual>
  <collision  name="G_collision" >
   <origin  rpy="0.0 0.0 0.0"  xyz="0.0 0.0 0.0" />
   <geometry >
    <sphere  radius="0.02" />
   </geometry>
  </collision>
  <inertial >
   <origin  rpy="0.0 0.0 0.0"  xyz="0.0 0.0 0.0" />
   <mass  value="0.047249553509990494" />
   <inertia  iyy="7.55992856159848e-06"  ixx="7.55992856159848e-06"  ixy="0.0"  izz="7.55992856159848e-06"  ixz="0.0"  iyz="0.0" />
  </inertial>
 </link>
 <link  name="L6" >
  <visual >
   <origin  rpy="0.0 -0.05297851195307901 0.0"  xyz="-0.008603636141404636 0.0 0.16224663505260734" />
   <geometry >
    <box  size="0.02 0.02 0.3249491845858219" />
   </geometry>
   <material name="L6_">
    <color  rgba="0.9338020296180713 0.31857780988113427 0.8094810326335653 0.7" />
   </material>
  </visual>
  <collision  name="L6_0collision" >
   <origin  rpy="0.0 -0.05297851195307901 0.0"  xyz="-0.008603636141404636 0.0 0.16224663505260734" />
   <geometry >
    <box  size="0.02 0.02 0.3249491845858219" />
   </geometry>
  </collision>
  <visual >
   <origin  rpy="0.0 0.0 0.0"  xyz="2.7755575615628914e-17 0.0 0.20723453410371823" />
   <geometry >
    <box  size="0.02 0.02 0.41446906820743645" />
   </geometry>
   <material name="L6_">
    <color  rgba="0.9338020296180713 0.31857780988113427 0.8094810326335653 0.7" />
   </material>
  </visual>
  <collision  name="L6_1collision" >
   <origin  rpy="0.0 0.0 0.0"  xyz="2.7755575615628914e-17 0.0 0.20723453410371823" />
   <geometry >
    <box  size="0.02 0.02 0.41446906820743645" />
   </geometry>
  </collision>
  <visual >
   <origin  rpy="0.0 0.1889616931375886 0.0"  xyz="-0.00860363614140458 0.0 0.36948116915632556" />
   <geometry >
    <box  size="0.02 0.02 0.09160641060289676" />
   </geometry>
   <material name="L6_">
    <color  rgba="0.9338020296180713 0.31857780988113427 0.8094810326335653 0.7" />
   </material>
  </visual>
  <collision  name="L6_2collision" >
   <origin  rpy="0.0 0.1889616931375886 0.0"  xyz="-0.00860363614140458 0.0 0.36948116915632556" />
   <geometry >
    <box  size="0.02 0.02 0.09160641060289676" />
   </geometry>
  </collision>
  <inertial >
   <origin  rpy="0.0 0.0 0.0"  xyz="-0.00574 0.0 0.24632" />
   <mass  value="0.10055953774321144" />
   <inertia  iyy="0.0007982424938455275"  ixx="0.0007999403268716969"  ixy="7.77549775799846e-23"  izz="5.006136156711119e-06"  ixz="1.127218193266216e-05"  iyz="0.0" />
  </inertial>
 </link>
 <link  name="EE" >
  <visual >
   <origin  rpy="0.0 0.0 0.0"  xyz="0.0 0.0 0.0" />
   <geometry >
    <sphere  radius="0.02" />
   </geometry>
   <material name="EE_">
    <color  rgba="0.06555796778691025 0.9586798728904428 0.6235813953121928 0.7" />
   </material>
  </visual>
  <collision  name="EE_collision" >
   <origin  rpy="0.0 0.0 0.0"  xyz="0.0 0.0 0.0" />
   <geometry >
    <sphere  radius="0.02" />
   </geometry>
  </collision>
  <inertial >
   <origin  rpy="0.0 0.0 0.0"  xyz="0.0 0.0 0.0" />
   <mass  value="0.047249553509990494" />
   <inertia  iyy="7.55992856159848e-06"  ixx="7.55992856159848e-06"  ixy="0.0"  izz="7.55992856159848e-06"  ixz="0.0"  iyz="0.0" />
  </inertial>
 </link>
 <link  name="L3" >
  <visual >
   <origin  rpy="0.0 0.0 0.0"  xyz="0.0 0.0 0.18861" />
   <geometry >
    <box  size="0.02 0.02 0.3772164653355748" />
   </geometry>
   <material name="L3_">
    <color  rgba="0.17713714233133848 0.5456505310703439 0.1626445122303456 0.7" />
   </material>
  </visual>
  <collision  name="L3_collision" >
   <origin  rpy="0.0 0.0 0.0"  xyz="0.0 0.0 0.18861" />
   <geometry >
    <box  size="0.02 0.02 0.3772164653355748" />
   </geometry>
  </collision>
  <inertial >
   <origin  rpy="0.0 0.0 0.0"  xyz="0.0 0.0 0.18861" />
   <mass  value="0.2127500864492642" />
   <inertia  iyy="0.0025298159180522826"  ixx="0.0025298159180522826"  ixy="0.0"  izz="1.4183339096617613e-05"  ixz="0.0"  iyz="0.0" />
  </inertial>
 </link>
 <link  name="L4" >
  <visual >
   <origin  rpy="0.0 4.440892098500626e-16 0.0"  xyz="-5.551115123125783e-17 0.0 0.5359497273105445" />
   <geometry >
    <box  size="0.02 0.02 1.071899454621089" />
   </geometry>
   <material name="L4_">
    <color  rgba="0.9017222272963605 0.9027480451842569 0.0729823810295438 0.7" />
   </material>
  </visual>
  <collision  name="L4_0collision" >
   <origin  rpy="0.0 4.440892098500626e-16 0.0"  xyz="-5.551115123125783e-17 0.0 0.5359497273105445" />
   <geometry >
    <box  size="0.02 0.02 1.071899454621089" />
   </geometry>
  </collision>
  <visual >
   <origin  rpy="3.141592653589793 0.22450775114872523 3.141592653589793"  xyz="0.027072813316937755 0.0 0.9533448815741774" />
   <geometry >
    <box  size="0.02 0.02 0.24321286159435923" />
   </geometry>
   <material name="L4_">
    <color  rgba="0.9017222272963605 0.9027480451842569 0.0729823810295438 0.7" />
   </material>
  </visual>
  <collision  name="L4_1collision" >
   <origin  rpy="3.141592653589793 0.22450775114872523 3.141592653589793"  xyz="0.027072813316937755 0.0 0.9533448815741774" />
   <geometry >
    <box  size="0.02 0.02 0.24321286159435923" />
   </geometry>
  </collision>
  <visual >
   <origin  rpy="0.0 0.06477062209215423 0.0"  xyz="0.02707281331693781 0.0 0.417395154263633" />
   <geometry >
    <box  size="0.02 0.02 0.8365444447814013" />
   </geometry>
   <material name="L4_">
    <color  rgba="0.9017222272963605 0.9027480451842569 0.0729823810295438 0.7" />
   </material>
  </visual>
  <collision  name="L4_2collision" >
   <origin  rpy="0.0 0.06477062209215423 0.0"  xyz="0.02707281331693781 0.0 0.417395154263633" />
   <geometry >
    <box  size="0.02 0.02 0.8365444447814013" />
   </geometry>
  </collision>
  <inertial >
   <origin  rpy="0.0 0.0 0.0"  xyz="0.01805 0.0 0.63556" />
   <mass  value="0.8183452139914555" />
   <inertia  iyy="0.04337064931756292"  ixx="0.043264639563651376"  ixy="8.429883649311612e-21"  izz="0.00016056610151095593"  ixz="-0.0007356428124067383"  iyz="9.37777280959548e-20" />
  </inertial>
 </link>
 <link  name="L8" >
  <visual >
   <origin  rpy="0.0 0.0 0.0"  xyz="-0.0 0.0 0.1893" />
   <geometry >
    <box  size="0.02 0.02 0.3785900609862303" />
   </geometry>
   <material name="L8_">
    <color  rgba="0.10420351058316157 0.9412420404536782 0.8427520062693113 0.7" />
   </material>
  </visual>
  <collision  name="L8_collision" >
   <origin  rpy="0.0 0.0 0.0"  xyz="-0.0 0.0 0.1893" />
   <geometry >
    <box  size="0.02 0.02 0.3785900609862303" />
   </geometry>
  </collision>
  <inertial >
   <origin  rpy="0.0 0.0 0.0"  xyz="-0.0 0.0 0.1893" />
   <mass  value="0.21352479439623392" />
   <inertia  iyy="0.0025575009522997415"  ixx="0.0025575009522997415"  ixy="0.0"  izz="1.4234986293082262e-05"  ixz="0.0"  iyz="0.0" />
  </inertial>
 </link>
 <link  name="L5" >
  <visual >
   <origin  rpy="0.0 0.0 0.0"  xyz="0.0 0.0 0.28823" />
   <geometry >
    <box  size="0.02 0.02 0.5764582971335448" />
   </geometry>
   <material name="L5_">
    <color  rgba="0.7347828391680242 0.07258411530814457 0.8457535229679948 0.7" />
   </material>
  </visual>
  <collision  name="L5_collision" >
   <origin  rpy="0.0 0.0 0.0"  xyz="0.0 0.0 0.28823" />
   <geometry >
    <box  size="0.02 0.02 0.5764582971335448" />
   </geometry>
  </collision>
  <inertial >
   <origin  rpy="0.0 0.0 0.0"  xyz="0.0 0.0 0.28823" />
   <mass  value="0.32512247958331925" />
   <inertia  iyy="0.00901413368137422"  ixx="0.00901413368137422"  ixy="0.0"  izz="2.1674831972221282e-05"  ixz="0.0"  iyz="0.0" />
  </inertial>
 </link>
 <joint  name="Ground_main"  type="revolute" >
  <parent  link="G" />
  <child  link="L7" />
  <origin  rpy="3.141592653589793 -0.19083519881055921 3.141592653589793"  xyz="0.0 0.0 0.0" />
  <axis  xyz="0 1 0" />
  <limit  velocity="17.907078125461823"  lower="-3.141592653589793"  effort="5.3999999999999995"  upper="3.141592653589793" />
  <dynamics  damping="0.05"  friction="0" />
 </joint>
 <joint  name="J0m"  type="revolute" >
  <parent  link="L7" />
  <child  link="L6" />
  <origin  rpy="0.0 -0.4033487460974359 0.0"  xyz="4.511719636526899e-18 0.0 0.46087762980918395" />
  <axis  xyz="0 1 0" />
  <limit  velocity="6.283185307179586"  lower="-3.141592653589793"  effort="600.0"  upper="3.141592653589793" />
  <dynamics  damping="0.05"  friction="0" />
 </joint>
 <joint  name="EE_JJ"  type="revolute" >
  <parent  link="L6" />
  <child  link="EE" />
  <origin  rpy="3.141592653589793 -0.21251354728687688 3.141592653589793"  xyz="8.326672684688674e-17 0.0 0.41446906820743645" />
  <axis  xyz="0 0 0" />
 </joint>
 <joint  name="J0_0"  type="revolute" >
  <parent  link="G" />
  <child  link="L3" />
  <origin  rpy="3.141592653589793 -0.6776744833942576 3.141592653589793"  xyz="-0.44803263751078415 0.0 0.0" />
  <axis  xyz="0 1 0" />
  <limit  velocity="6.283185307179586"  lower="-3.141592653589793"  effort="600.0"  upper="3.141592653589793" />
  <dynamics  damping="0.05"  friction="0" />
 </joint>
 <joint  name="J1_0"  type="revolute" >
  <parent  link="L3" />
  <child  link="L4" />
  <origin  rpy="3.141592653589793 -0.7272651080805895 3.141592653589793"  xyz="5.551115123125783e-17 0.0 0.3772164653355747" />
  <axis  xyz="0 1 0" />
  <limit  velocity="6.283185307179586"  lower="-3.141592653589793"  effort="600.0"  upper="3.141592653589793" />
  <dynamics  damping="0.05"  friction="0" />
 </joint>
 <joint  name="J2_0"  type="revolute" >
  <parent  link="L4" />
  <child  link="L8" />
  <origin  rpy="3.141592653589793 -0.09014337909294401 3.141592653589793"  xyz="-1.1102230246251565e-16 0.0 1.071899454621089" />
  <axis  xyz="0 1 0" />
  <limit  velocity="6.283185307179586"  lower="-3.141592653589793"  effort="600.0"  upper="3.141592653589793" />
  <dynamics  damping="0.05"  friction="0" />
 </joint>
 <link  name="J3_0_L8Pseudo" >
  <visual >
   <geometry >
    <sphere  radius="0.03" />
   </geometry>
   <material name = "J3_0_">
    <color  rgba="0.10420351058316157 0.9412420404536782 0.8427520062693113 0.5" />
   </material>
  </visual>
 </link>
 <joint  name="J3_0_L8_revolute"  type="revolute" >
  <parent  link="L8" />
  <child  link="J3_0_L8Pseudo" />
  <origin  rpy="0.0 0.0 0.0"  xyz="-5.551115123125783e-17 0.0 0.3785900609862303" />
  <axis  xyz="0 1 0" />
  <limit  velocity="6.283185307179586"  lower="-3.141592653589793"  effort="600.0"  upper="3.141592653589793" />
  <dynamics  damping="0.05"  friction="0" />
 </joint>
 <joint  name="J3_0_L8_fix"  type="fixed" >
  <parent  link="L7" />
  <child  link="J3_0_L7Pseudo" />
  <origin  rpy="0.0 1.3042477717572325 0.0"  xyz="-0.02283640547652227 0.0 0.14381235562954064" />
 </joint>
 <link  name="J3_0_L7Pseudo" >
  <visual >
   <geometry >
    <sphere  radius="0.03" />
   </geometry>
   <material name = "J3_0_">
    <color  rgba="0.22805773121194928 0.6120967953154014 0.1518055185515783 0.5" />
   </material>
  </visual>
 </link>
 <joint  name="J4_1_0"  type="revolute" >
  <parent  link="L4" />
  <child  link="L5" />
  <origin  rpy="3.141592653589793 1.1418973044975522 3.141592653589793"  xyz="0.05414562663387562 0.0 0.834790308527266" />
  <axis  xyz="0 1 0" />
  <limit  velocity="6.283185307179586"  lower="-3.141592653589793"  effort="600.0"  upper="3.141592653589793" />
  <dynamics  damping="0.05"  friction="0" />
 </joint>
 <link  name="J5_1_0_L6Pseudo" >
  <visual >
   <geometry >
    <sphere  radius="0.03" />
   </geometry>
   <material name = "J5_1_0_">
    <color  rgba="0.9338020296180713 0.31857780988113427 0.8094810326335653 0.5" />
   </material>
  </visual>
 </link>
 <joint  name="J5_1_0_L6_revolute"  type="revolute" >
  <parent  link="L6" />
  <child  link="J5_1_0_L6Pseudo" />
  <origin  rpy="0.0 0.0 0.0"  xyz="-0.017207272282809244 0.0 0.32449327010521467" />
  <axis  xyz="0 1 0" />
  <limit  velocity="6.283185307179586"  lower="-3.141592653589793"  effort="600.0"  upper="3.141592653589793" />
  <dynamics  damping="0.05"  friction="0" />
 </joint>
 <joint  name="J5_1_0_L6_fix"  type="fixed" >
  <parent  link="L5" />
  <child  link="J5_1_0_L5Pseudo" />
  <origin  rpy="0.0 -0.47555583426417214 0.0"  xyz="1.6653345369377348e-16 0.0 0.5764582971335448" />
 </joint>
 <link  name="J5_1_0_L5Pseudo" >
  <visual >
   <geometry >
    <sphere  radius="0.03" />
   </geometry>
   <material name="J5_1_">
    <color  rgba="0.7347828391680242 0.07258411530814457 0.8457535229679948 0.5" />
   </material>
  </visual>
 </link>
</robot>
